Workbook

Sheet TONG_HOP_DON_HANG_VA_HOAN_THUE
A1: CÔNG TY TNHH GLOBAL SOLUTION SERVICE (G-SS CO.,LTD)
A2: Tầng 18, Tòa nhà CEO Tower, Lô HH2-1, Khu đô thị Mễ Trì Hạ, đường Phạm Hùng, Phường Từ Liêm, Thành phố Hà Nội
A3: MST: 0109469047 | Tài khoản MB Bank: 6868886868 (VND) & 9489773866038 (USD) — CN Hà Nội
A5: BẢNG MASTER DASHBOARD: TỔNG HỢP TOÀN BỘ ĐƠN HÀNG XUẤT KHẨU & THEO DÕI DỒN TÍCH LŨY HOÀN THUẾ GTGT 0%
A6: Hệ thống quản trị tài chính hợp nhất đa Sheet — Quản trị Doanh thu 2 đợt USD, 2 Tầng Lợi nhuận & Tiến độ tích lũy hoàn thuế ≥ 300 triệu đồng
A8: TỔNG DOANH THU THỰC TẾ (VNĐ) | D8: TỔNG CHI PHÍ THỰC TẾ (CHƯA VAT) | G8: LỢI NHUẬN TRƯỚC THUẾ (EBT) | J8: THUẾ TNDN 20% TẠM NỘP | M8: ★ LÃI RÒNG TẦNG 1 (TIỀN TƯƠI) | P8: ★★ QUỸ HOÀN THUẾ GTGT ĐÃ TÍCH LŨY
A9: =SUM(G15:G20) | D9: =SUM(L15:L20) | G9: =SUM(M15:M20) | J9: =SUM(N15:N20) | M9: =SUM(O15:O20) | P9: =MAX(Q15:Q20)
A12: DANH MỤC CÁC ĐƠN HÀNG XUẤT KHẨU (SỐ LIỆU THỰC TẾ & CÁC DÒNG CHỜ PHÁT SINH TỰ ĐỘNG)
A14: STT | B14: MÃ ĐƠN | C14: HỢP ĐỒNG / TỜ KHAI HQ | D14: THỊ TRƯỜNG / ĐỐI TÁC | E14: USD ĐỢT 1 (CỌC) | F14: USD ĐỢT 2 (QT) | G14: TỔNG DOANH THU (VNĐ) | H14: TỶ GIÁ BQ | I14: GIÁ VỐN (CHƯA VAT) | J14: VẬN TẢI & LOG | K14: PHỤ PHÍ CỬA KHẨU | L14: TỔNG CHI PHÍ THỰC TẾ | M14: LỢI NHUẬN TRƯỚC THUẾ | N14: THUẾ TNDN 20% | O14: ★ LÃI RÒNG TẦNG 1 | P14: THUẾ GTGT ĐẦU VÀO | Q14: ★★ LŨY KẾ HOÀN THUẾ (TK 1331) | R14: CÒN THIẾU ĐỦ 300M | S14: TIẾN ĐỘ 300M | T14: TRẠNG THÁI NỘP HỒ SƠ HOÀN THUẾ | U14: ★★ LÃI RÒNG TẦNG 2 | V14: SHEET CHI TIẾT
A15: 1 | B15: 269901 | C15: GSSDIX_FCA_269901 / TK 107382910430 | D15: Thái Lan (Duangmanee Co., Ltd) | E15: ='DON_269901'!E17 | F15: ='DON_269901'!E18 | G15: ='DON_269901'!G19 | H15: ='DON_269901'!F19 | I15: ='DON_269901'!G24 | J15: ='DON_269901'!G32 | K15: ='DON_269901'!G44 | L15: ='DON_269901'!G52 | M15: ='DON_269901'!G56 | N15: ='DON_269901'!G58 | O15: ='DON_269901'!G60 | P15: ='DON_269901'!G53 | Q15: =P15 | R15: =MAX(0, 300000000-Q15) | S15: =Q15/300000000 | T15: =IF(Q15>=300000000, "ĐỦ ĐIỀU KIỆN HOÀN THUẾ", "ĐANG TÍCH LŨY (Chưa đủ 300M)") | U15: ='DON_269901'!G63 | V15: DON_269901
A16: 2 | B16: [Chờ phát sinh] | C16: Chờ hợp đồng mới | D16: Chờ đối tác | Q16: =IF(P16="","",Q15+P16) | R16: =IF(Q16="","",MAX(0, 300000000-Q16)) | S16: =IF(Q16="","",Q16/300000000) | T16: =IF(Q16="","",IF(Q16>=300000000, "ĐỦ ĐIỀU KIỆN HOÀN THUẾ", "ĐANG TÍCH LŨY (Chưa đủ 300M)")) | V16: DON_TEMPLATE
A17: 3 | B17: [Chờ phát sinh] | C17: Chờ hợp đồng mới | D17: Chờ đối tác | Q17: =IF(P17="","",Q16+P17) | R17: =IF(Q17="","",MAX(0, 300000000-Q17)) | S17: =IF(Q17="","",Q17/300000000) | T17: =IF(Q17="","",IF(Q17>=300000000, "ĐỦ ĐIỀU KIỆN HOÀN THUẾ", "ĐANG TÍCH LŨY (Chưa đủ 300M)")) | V17: DON_TEMPLATE
A18: 4 | B18: [Chờ phát sinh] | C18: Chờ hợp đồng mới | D18: Chờ đối tác | Q18: =IF(P18="","",Q17+P18) | R18: =IF(Q18="","",MAX(0, 300000000-Q18)) | S18: =IF(Q18="","",Q18/300000000) | T18: =IF(Q18="","",IF(Q18>=300000000, "ĐỦ ĐIỀU KIỆN HOÀN THUẾ", "ĐANG TÍCH LŨY (Chưa đủ 300M)")) | V18: DON_TEMPLATE
A19: 5 | B19: [Chờ phát sinh] | C19: Chờ hợp đồng mới | D19: Chờ đối tác | Q19: =IF(P19="","",Q18+P19) | R19: =IF(Q19="","",MAX(0, 300000000-Q19)) | S19: =IF(Q19="","",Q19/300000000) | T19: =IF(Q19="","",IF(Q19>=300000000, "ĐỦ ĐIỀU KIỆN HOÀN THUẾ", "ĐANG TÍCH LŨY (Chưa đủ 300M)")) | V19: DON_TEMPLATE
A21: — | B21: TỔNG CỘNG | C21: TỔNG HỢP CÁC ĐƠN HÀNG THỰC TẾ ĐÃ PHÁT SINH | D21: G-SS CO.,LTD | E21: =SUM(E15:E20) | F21: =SUM(F15:F20) | G21: =SUM(G15:G20) | H21: =IF(SUM(E21:F21)>0, G21/SUM(E21:F21), 0) | I21: =SUM(I15:I20) | J21: =SUM(J15:J20) | K21: =SUM(K15:K20) | L21: =SUM(L15:L20) | M21: =SUM(M15:M20) | N21: =SUM(N15:N20) | O21: =SUM(O15:O20) | P21: =SUM(P15:P20) | Q21: =MAX(Q15:Q20) | R21: =MAX(0, 300000000-Q21) | S21: =Q21/300000000 | T21: =IF(Q21>=300000000, "ĐỦ ĐIỀU KIỆN HOÀN THUẾ", "ĐANG TÍCH LŨY (Chưa đủ 300M)") | U21: =SUM(U15:U20) | V21: ALL ORDERS

Sheet DON_269901
A1: CÔNG TY TNHH GLOBAL SOLUTION SERVICE (G-SS CO.,LTD)
A2: Tầng 18, Tòa nhà CEO Tower, Lô HH2-1, Khu đô thị Mễ Trì Hạ, đường Phạm Hùng, Phường Từ Liêm, Thành phố Hà Nội
A3: MST: 0109469047 | Hotline: 0966688525 | Email: safetylife.1st@gmail.com
A5: BẢNG QUYẾT TOÁN TÀI CHÍNH & TỔNG CHI PHÍ ĐƠN HÀNG 269901
A6: Đơn hàng: GSSDIX_FCA_269901 (PO260901) | Tờ khai Hải quan B11: 107382910430 (Luồng Vàng) | Khách hàng: DUANGMANEE IMPORT-EXPORT CO., LTD (Thái Lan)
A8: DOANH THU THỰC NHẬN (FCA) | C8: TỔNG CHI PHÍ THỰC TẾ | E8: LỢI NHUẬN TRƯỚC THUẾ (EBT) | G8: THUẾ TNDN 20% TẠM NỘP | I8: ★ LÃI RÒNG TRƯỚC HOÀN THUẾ (TIỀN TƯƠI) | K8: ★★ LÃI RÒNG SAU HOÀN THUẾ (TỔNG THỂ)
A9: =G19 | C9: =G52 | E9: =G56 | G9: =G58 | I9: =G60 | K9: =G63
A14: PHẦN I: DOANH THU XUẤT KHẨU & THEO DÕI NGOẠI TỆ USD VỀ 2 ĐỢT (BÊN MUA: DUANGMANEE IMPORT-EXPORT CO., LTD (Thái Lan))
A15: STT | B15: DANH MỤC HẠNG MỤC / KHOẢN MỤC CHI PHÍ | C15: QUY CÁCH / ĐỐI TÁC THỰC HIỆN | D15: ĐVT | E15: SỐ TIỀN USD / SỐ LƯỢNG | F15: TỶ GIÁ (VND/USD) / ĐƠN GIÁ | G15: THÀNH TIỀN QUY ĐỔI VNĐ (CHƯA VAT) | H15: THUẾ GTGT (8% / 0%) | I15: TỔNG THANH TOÁN (GỒM VAT) | J15: SỐ HÓA ĐƠN / CHỨNG TỪ ĐỐI CHIẾU | K15: HÌNH THỨC TT | L15: GHI CHÚ KIỂM TOÁN THUẾ
A16: 1.1 | B16: Doanh thu theo Hợp đồng Ngoại thương (FCA) | C16: 1,300 thùng Snack Quẩy Giòn Giòn | D16: USD | E16: 20540 | F16: 26008 | G16: =E16*F16 | H16: 0 | I16: =G16 | J16: HĐ GSSDIX_FCA_269901 (PO260901) | K16: MB Bank USD | L16: Thuế suất GTGT 0% (Hợp đồng gốc)
A17: 1.2 | B17: Tiền về ĐỢT 1 — Tạm ứng cọc hợp đồng [Nhập liệu] | C17: Nhận vào TK MB 9489773866038 | D17: USD | E17: 8532 | F17: 26008 | G17: =E17*F17 | H17: 0 | I17: =G17 | J17: Giấy báo Có MB Bank Đợt 1 | K17: Chuyển khoản T/T | L17: Điện MT103 đối tác chuyển
A18: 1.3 | B18: Tiền về ĐỢT 2 — Quyết toán trước giao hàng [Nhập liệu] | C18: Nhận vào TK MB 9489773866038 | D18: USD | E18: 12008 | F18: 26008 | G18: =E18*F18 | H18: 0 | I18: =G18 | J18: Giấy báo Có MB Bank Đợt 2 | K18: Chuyển khoản T/T | L18: Điện MT103 đối tác chuyển
A19: — | B19: ➤ TỔNG DOANH THU NGOẠI TỆ THỰC NHẬN QUY ĐỔI VNĐ | C19: Tổng hợp 2 đợt thanh toán kiều hối USD thực tế | D19: USD | E19: =E17+E18 | F19: =IF(E19>0, G19/E19, 0) | G19: =G17+G18 | H19: 0 | I19: =G19+H19 | J19: HĐ MISA 0% / 2 Báo Có | K19: MB Bank USD | L19: Chỉ tiêu [29] trên Tờ khai 01/GTGT
A21: PHẦN II: CHI PHÍ GIÁ VỐN HÀNG BÁN (NHÀ CUNG CẤP: CÔNG TY TNHH ĐẦU TƯ TM CN THIÊN LONG)
A22: STT | B22: DANH MỤC HẠNG MỤC / KHOẢN MỤC CHI PHÍ | C22: QUY CÁCH / ĐỐI TÁC THỰC HIỆN | D22: ĐVT | E22: SỐ TIỀN USD / SỐ LƯỢNG | F22: TỶ GIÁ (VND/USD) / ĐƠN GIÁ | G22: THÀNH TIỀN QUY ĐỔI VNĐ (CHƯA VAT) | H22: THUẾ GTGT (8% / 0%) | I22: TỔNG THANH TOÁN (GỒM VAT) | J22: SỐ HÓA ĐƠN / CHỨNG TỪ ĐỐI CHIẾU | K22: HÌNH THỨC TT | L22: GHI CHÚ KIỂM TOÁN THUẾ
A23: 2.1 | B23: Mua Snack Quẩy Giòn Giòn thành phẩm | C23: Quy cách: 22g/cốc, 300 cốc/thùng 5 lớp | D23: Thùng | E23: 1300 | F23: 337000 | G23: =E23*F23 | H23: =G23*0.08 | I23: =G23+H23 | J23: HĐNT 269901 & PL01 | K23: MB Bank UNC | L23: Hóa đơn VAT 8% (Được khấu trừ/hoàn)
A24: — | B24: CỘNG GIÁ VỐN MUA HÀNG THIÊN LONG | C24: Giao tại cửa kho nhà máy Phú Thọ | D24: Thùng | E24: 1300 | G24: =SUM(G23:G23) | H24: =SUM(H23:H23) | I24: =SUM(I23:I23) | J24: HĐ GTGT Thiên Long | K24: MB Bank UNC | L24: Kê khai Chỉ tiêu [23], [24], [25]
A26: PHẦN III: CHI PHÍ VẬN TẢI NỘI ĐỊA & ĐẠI LÝ HẢI QUAN CHÍNH TUYẾN
A27: STT | B27: DANH MỤC HẠNG MỤC / KHOẢN MỤC CHI PHÍ | C27: QUY CÁCH / ĐỐI TÁC THỰC HIỆN | D27: ĐVT | E27: SỐ TIỀN USD / SỐ LƯỢNG | F27: TỶ GIÁ (VND/USD) / ĐƠN GIÁ | G27: THÀNH TIỀN QUY ĐỔI VNĐ (CHƯA VAT) | H27: THUẾ GTGT (8% / 0%) | I27: TỔNG THANH TOÁN (GỒM VAT) | J27: SỐ HÓA ĐƠN / CHỨNG TỪ ĐỐI CHIẾU | K27: HÌNH THỨC TT | L27: GHI CHÚ KIỂM TOÁN THUẾ
A28: 3.1 | B28: Cước vận chuyển container HOWO 15.6m | C28: Tuyến: Kho Phú Thọ ➔ Cửa khẩu Lao Bảo | D28: Chuyến | E28: 1 | F28: 22000000 | G28: =E28*F28 | H28: =G28*0.08 | I28: =G28+H28 | J28: HĐ 00000217 (Vĩnh Thành) | K28: MB Bank UNC | L28: Hóa đơn VAT 8% (Hợp đồng VC)
A29: 3.2 | B29: Phí lưu xe HOWO 15.6m tại bãi Lao Bảo | C29: Lưu xe 2 ngày chờ đối tác | D29: Ngày | E29: 2 | F29: 2314815 | G29: =E29*F29 | H29: =G29*0.08 | I29: =G29+H29 | J29: HĐ 00000217 (Vĩnh Thành) | K29: MB Bank UNC | L29: Hóa đơn VAT 8% (Phụ lục điều xe)
A30: 3.3 | B30: Phí dịch vụ Đại lý Hải quan & C/O Bình An | C30: Khai B11, C/O Form D eCoSys, Biên phòng | D30: Lô | E30: 1 | F30: 8200000 | G30: 8200000 | H30: 0 | I30: =G30+H30 | J30: Phiếu thu / HĐ Bình An | K30: Chuyển khoản | L30: Dịch vụ thông quan trọn gói cửa khẩu
A31: 3.4 | B31: Lệ phí Hải quan B11 & Hạ tầng bãi Lao Bảo | C31: Phí khai hải quan 20k + Phí bến bãi 250k | D31: Lô | E31: 1 | F31: 270000 | G31: 270000 | H31: 0 | I31: =G31+H31 | J31: Biên lai thu phí Nhà nước | K31: Tiền mặt | L31: Lệ phí NSNN không chịu VAT
A32: — | B32: CỘNG CHI PHÍ VẬN TẢI & LOGISTICS CHÍNH | C32: Tổng chi phí vận hành logistics cố định | D32: Gói | E32: 1 | G32: =SUM(G28:G31) | H32: =SUM(H28:H31) | I32: =SUM(I28:I31) | J32: HĐ Vĩnh Thành + Biên lai | K32: UNC / TM | L32: Kê khai vào chi phí hợp lý được trừ
A34: PHẦN IV: PHỤ PHÍ PHÁT SINH NGOÀI THỰC TẾ CỬA KHẨU & HIỆN TRƯỜNG (KHU VỰC NHẬP THÊM CHI PHÍ LINH HOẠT)
A35: STT | B35: DANH MỤC HẠNG MỤC / KHOẢN MỤC CHI PHÍ | C35: QUY CÁCH / ĐỐI TÁC THỰC HIỆN | D35: ĐVT | E35: SỐ TIỀN USD / SỐ LƯỢNG | F35: TỶ GIÁ (VND/USD) / ĐƠN GIÁ | G35: THÀNH TIỀN QUY ĐỔI VNĐ (CHƯA VAT) | H35: THUẾ GTGT (8% / 0%) | I35: TỔNG THANH TOÁN (GỒM VAT) | J35: SỐ HÓA ĐƠN / CHỨNG TỪ ĐỐI CHIẾU | K35: HÌNH THỨC TT | L35: GHI CHÚ KIỂM TOÁN THUẾ
A36: 4.1 | B36: Công bốc xếp chuyển tải 'thùng đấu thùng' | C36: Cross-docking 1,300 thùng xe sang xe nhận | D36: Thùng | E36: 1300 | F36: =G36/E36 | G36: 2500000 | H36: 0 | I36: =G36+H36 | J36: Bảng kê 01/TNDN & Mẫu 08 | K36: Tiền mặt | L36: Có CCCD Tổ trưởng (Chi phí hợp lý TT96)
A37: 4.2 | B37: Phí xử lý hồ sơ thay đổi phương án giao hàng | C37: Công văn 15/CV-GSS hủy xuất cảnh xe sang hàng | D37: Vụ | E37: 1 | F37: 2000000 | G37: 2000000 | H37: 0 | I37: =G37+H37 | J37: Công văn 15 có mộc Hải quan | K37: Chuyển khoản | L37: Phát sinh đột xuất tại hiện trường Lao Bảo
A38: 4.3 | B38: Tiền phòng khách sạn nhân viên hiện trường | C38: Đồng Thanh Tùng lưu trú 2 đêm Lao Bảo | D38: Đêm | E38: 2 | F38: 370370 | G38: =E38*F38 | H38: =G38*0.08 | I38: =G38+H38 | J38: HĐ 00001188 (Dư Hùng Phát) | K38: Hoàn ứng | L38: Hóa đơn VAT 8% (Giấy thanh toán KT-LOG-07)
A39: 4.4 | B39: [Người dùng nhập thêm khoản phát sinh 01] | C39: Mô tả khoản chi phí phát sinh thực tế... | D39: Gói | E39: 0 | F39: 0 | G39: 0 | H39: =G39*0.08 | I39: =G39+H39 | J39: Chứng từ kèm theo... | K39: [Hình thức] | L39: Ghi chú thuế...
A40: 4.5 | B40: [Người dùng nhập thêm khoản phát sinh 02] | C40: Mô tả khoản chi phí phát sinh thực tế... | D40: Gói | E40: 0 | F40: 0 | G40: 0 | H40: =G40*0.08 | I40: =G40+H40 | J40: Chứng từ kèm theo... | K40: [Hình thức] | L40: Ghi chú thuế...
A41: 4.6 | B41: [Người dùng nhập thêm khoản phát sinh 03] | C41: Mô tả khoản chi phí phát sinh thực tế... | D41: Gói | E41: 0 | F41: 0 | G41: 0 | H41: =G41*0.08 | I41: =G41+H41 | J41: Chứng từ kèm theo... | K41: [Hình thức] | L41: Ghi chú thuế...
A42: 4.7 | B42: [Người dùng nhập thêm khoản phát sinh 04] | C42: Mô tả khoản chi phí phát sinh thực tế... | D42: Gói | E42: 0 | F42: 0 | G42: 0 | H42: =G42*0.08 | I42: =G42+H42 | J42: Chứng từ kèm theo... | K42: [Hình thức] | L42: Ghi chú thuế...
A43: 4.8 | B43: [Người dùng nhập thêm khoản phát sinh 05] | C43: Mô tả khoản chi phí phát sinh thực tế... | D43: Gói | E43: 0 | F43: 0 | G43: 0 | H43: =G43*0.08 | I43: =G43+H43 | J43: Chứng từ kèm theo... | K43: [Hình thức] | L43: Ghi chú thuế...
A44: — | B44: CỘNG TOÀN BỘ PHỤ PHÍ PHÁT SINH NGOÀI | C44: Tự động cộng dồn các khoản chi thực tế và nhập thêm | D44: Mục | E44: =COUNTIF(G36:G43,">0") | G44: =SUM(G36:G43) | H44: =SUM(H36:H43) | I44: =SUM(I36:I43) | J44: Bảng kê + Hóa đơn lẻ | K44: Đa dạng | L44: Tự động tính thuế và phân bổ vào P&L
A46: PHẦN V: BẢNG TỔNG HỢP P&L — PHÂN ĐỊNH 2 TẦNG LỢI NHUẬN (TRƯỚC KHI HOÀN THUẾ & SAU KHI HOÀN THUẾ)
A48: A | B48: TỔNG DOANH THU THỰC NHẬN TỪ 2 ĐỢT NGOẠI TỆ (FCA) | G48: =G19 | J48: Công thức Excel tự động
A49: B | B49: 1. Chi phí Giá vốn mua hàng Thiên Long (Phần II) | G49: =G24 | J49: Công thức Excel tự động
A50: C | B50: 2. Chi phí Vận tải & Logistics chính tuyến (Phần III) | G50: =G32 | J50: Công thức Excel tự động
A51: D | B51: 3. Phụ phí phát sinh ngoài thực tế cửa khẩu & hiện trường (Phần IV) | G51: =G44 | J51: Công thức Excel tự động
...

Sheet DON_TEMPLATE
A1: CÔNG TY TNHH GLOBAL SOLUTION SERVICE (G-SS CO.,LTD)
A2: Tầng 18, Tòa nhà CEO Tower, Lô HH2-1, Khu đô thị Mễ Trì Hạ, đường Phạm Hùng, Phường Từ Liêm, Thành phố Hà Nội
A3: MST: 0109469047 | Hotline: 0966688525 | Email: safetylife.1st@gmail.com
A5: BẢNG QUYẾT TOÁN TÀI CHÍNH & TỔNG CHI PHÍ ĐƠN HÀNG [YYMMDDNN]
A6: Đơn hàng: GSSDIX_FCA_[YYMMDDNN] | Tờ khai Hải quan B11: [Số Tờ khai B11 Thông quan] | Khách hàng: DUANGMANEE IMPORT-EXPORT CO., LTD
A8: DOANH THU THỰC NHẬN (FCA) | C8: TỔNG CHI PHÍ THỰC TẾ | E8: LỢI NHUẬN TRƯỚC THUẾ (EBT) | G8: THUẾ TNDN 20% TẠM NỘP | I8: ★ LÃI RÒNG TRƯỚC HOÀN THUẾ (TIỀN TƯƠI) | K8: ★★ LÃI RÒNG SAU HOÀN THUẾ (TỔNG THỂ)
A9: =G19 | C9: =G52 | E9: =G56 | G9: =G58 | I9: =G60 | K9: =G63
A14: PHẦN I: DOANH THU XUẤT KHẨU & THEO DÕI NGOẠI TỆ USD VỀ 2 ĐỢT (BÊN MUA: DUANGMANEE IMPORT-EXPORT CO., LTD)
A15: STT | B15: DANH MỤC HẠNG MỤC / KHOẢN MỤC CHI PHÍ | C15: QUY CÁCH / ĐỐI TÁC THỰC HIỆN | D15: ĐVT | E15: SỐ TIỀN USD / SỐ LƯỢNG | F15: TỶ GIÁ (VND/USD) / ĐƠN GIÁ | G15: THÀNH TIỀN QUY ĐỔI VNĐ (CHƯA VAT) | H15: THUẾ GTGT (8% / 0%) | I15: TỔNG THANH TOÁN (GỒM VAT) | J15: SỐ HÓA ĐƠN / CHỨNG TỪ ĐỐI CHIẾU | K15: HÌNH THỨC TT | L15: GHI CHÚ KIỂM TOÁN THUẾ
A16: 1.1 | B16: Doanh thu theo Hợp đồng Ngoại thương (FCA) | C16: [Số lượng thùng] | D16: USD | E16: 0 | F16: 0 | G16: =E16*F16 | H16: 0 | I16: =G16 | J16: HĐ GSSDIX_FCA_[YYMMDDNN] | K16: MB Bank USD | L16: Thuế suất GTGT 0% (Hợp đồng gốc)
A17: 1.2 | B17: Tiền về ĐỢT 1 — Tạm ứng cọc hợp đồng [Nhập liệu] | C17: Nhận vào TK MB 9489773866038 | D17: USD | E17: 0 | F17: 26000 | G17: =E17*F17 | H17: 0 | I17: =G17 | J17: Giấy báo Có MB Bank Đợt 1 | K17: Chuyển khoản T/T | L17: Điện MT103 đối tác chuyển
A18: 1.3 | B18: Tiền về ĐỢT 2 — Quyết toán trước giao hàng [Nhập liệu] | C18: Nhận vào TK MB 9489773866038 | D18: USD | E18: 0 | F18: 26000 | G18: =E18*F18 | H18: 0 | I18: =G18 | J18: Giấy báo Có MB Bank Đợt 2 | K18: Chuyển khoản T/T | L18: Điện MT103 đối tác chuyển
A19: — | B19: ➤ TỔNG DOANH THU NGOẠI TỆ THỰC NHẬN QUY ĐỔI VNĐ | C19: Tổng hợp 2 đợt thanh toán kiều hối USD thực tế | D19: USD | E19: =E17+E18 | F19: =IF(E19>0, G19/E19, 0) | G19: =G17+G18 | H19: 0 | I19: =G19+H19 | J19: HĐ MISA 0% / 2 Báo Có | K19: MB Bank USD | L19: Chỉ tiêu [29] trên Tờ khai 01/GTGT
A21: PHẦN II: CHI PHÍ GIÁ VỐN HÀNG BÁN (NHÀ CUNG CẤP: CÔNG TY TNHH ĐẦU TƯ TM CN THIÊN LONG)
A22: STT | B22: DANH MỤC HẠNG MỤC / KHOẢN MỤC CHI PHÍ | C22: QUY CÁCH / ĐỐI TÁC THỰC HIỆN | D22: ĐVT | E22: SỐ TIỀN USD / SỐ LƯỢNG | F22: TỶ GIÁ (VND/USD) / ĐƠN GIÁ | G22: THÀNH TIỀN QUY ĐỔI VNĐ (CHƯA VAT) | H22: THUẾ GTGT (8% / 0%) | I22: TỔNG THANH TOÁN (GỒM VAT) | J22: SỐ HÓA ĐƠN / CHỨNG TỪ ĐỐI CHIẾU | K22: HÌNH THỨC TT | L22: GHI CHÚ KIỂM TOÁN THUẾ
A23: 2.1 | B23: Mua Snack Quẩy Giòn Giòn thành phẩm | C23: Quy cách: 22g/cốc, 300 cốc/thùng 5 lớp | D23: Thùng | E23: 0 | F23: 337000 | G23: =E23*F23 | H23: =G23*0.08 | I23: =G23+H23 | J23: HĐNT [YYMMDDNN] & PL01 | K23: MB Bank UNC | L23: Hóa đơn VAT 8% (Được khấu trừ/hoàn)
A24: — | B24: CỘNG GIÁ VỐN MUA HÀNG THIÊN LONG | C24: Giao tại cửa kho nhà máy Phú Thọ | D24: Thùng | E24: 0 | G24: =SUM(G23:G23) | H24: =SUM(H23:H23) | I24: =SUM(I23:I23) | J24: HĐ GTGT Thiên Long | K24: MB Bank UNC | L24: Kê khai Chỉ tiêu [23], [24], [25]
A26: PHẦN III: CHI PHÍ VẬN TẢI NỘI ĐỊA & ĐẠI LÝ HẢI QUAN CHÍNH TUYẾN
A27: STT | B27: DANH MỤC HẠNG MỤC / KHOẢN MỤC CHI PHÍ | C27: QUY CÁCH / ĐỐI TÁC THỰC HIỆN | D27: ĐVT | E27: SỐ TIỀN USD / SỐ LƯỢNG | F27: TỶ GIÁ (VND/USD) / ĐƠN GIÁ | G27: THÀNH TIỀN QUY ĐỔI VNĐ (CHƯA VAT) | H27: THUẾ GTGT (8% / 0%) | I27: TỔNG THANH TOÁN (GỒM VAT) | J27: SỐ HÓA ĐƠN / CHỨNG TỪ ĐỐI CHIẾU | K27: HÌNH THỨC TT | L27: GHI CHÚ KIỂM TOÁN THUẾ
A28: 3.1 | B28: Cước vận chuyển container HOWO 15.6m | C28: Tuyến: Kho Phú Thọ ➔ Cửa khẩu Lao Bảo | D28: Chuyến | E28: 1 | F28: 0 | G28: =E28*F28 | H28: =G28*0.08 | I28: =G28+H28 | J28: HĐ 00000217 (Vĩnh Thành) | K28: MB Bank UNC | L28: Hóa đơn VAT 8% (Hợp đồng VC)
A29: 3.2 | B29: Phí lưu xe HOWO 15.6m tại bãi Lao Bảo | C29: [Số ngày lưu] | D29: Ngày | E29: 0 | F29: 0 | G29: =E29*F29 | H29: =G29*0.08 | I29: =G29+H29 | J29: HĐ 00000217 (Vĩnh Thành) | K29: MB Bank UNC | L29: Hóa đơn VAT 8% (Phụ lục điều xe)
A30: 3.3 | B30: Phí dịch vụ Đại lý Hải quan & C/O Bình An | C30: Khai B11, C/O Form D eCoSys, Biên phòng | D30: Lô | E30: 1 | F30: 0 | G30: 0 | H30: 0 | I30: =G30+H30 | J30: Phiếu thu / HĐ Bình An | K30: Chuyển khoản | L30: Dịch vụ thông quan trọn gói cửa khẩu
A31: 3.4 | B31: Lệ phí Hải quan B11 & Hạ tầng bãi Lao Bảo | C31: Phí khai hải quan 20k + Phí bến bãi 250k | D31: Lô | E31: 1 | F31: 0 | G31: 0 | H31: 0 | I31: =G31+H31 | J31: Biên lai thu phí Nhà nước | K31: Tiền mặt | L31: Lệ phí NSNN không chịu VAT
A32: — | B32: CỘNG CHI PHÍ VẬN TẢI & LOGISTICS CHÍNH | C32: Tổng chi phí vận hành logistics cố định | D32: Gói | E32: 1 | G32: =SUM(G28:G31) | H32: =SUM(H28:H31) | I32: =SUM(I28:I31) | J32: HĐ Vĩnh Thành + Biên lai | K32: UNC / TM | L32: Kê khai vào chi phí hợp lý được trừ
A34: PHẦN IV: PHỤ PHÍ PHÁT SINH NGOÀI THỰC TẾ CỬA KHẨU & HIỆN TRƯỜNG (KHU VỰC NHẬP THÊM CHI PHÍ LINH HOẠT)
A35: STT | B35: DANH MỤC HẠNG MỤC / KHOẢN MỤC CHI PHÍ | C35: QUY CÁCH / ĐỐI TÁC THỰC HIỆN | D35: ĐVT | E35: SỐ TIỀN USD / SỐ LƯỢNG | F35: TỶ GIÁ (VND/USD) / ĐƠN GIÁ | G35: THÀNH TIỀN QUY ĐỔI VNĐ (CHƯA VAT) | H35: THUẾ GTGT (8% / 0%) | I35: TỔNG THANH TOÁN (GỒM VAT) | J35: SỐ HÓA ĐƠN / CHỨNG TỪ ĐỐI CHIẾU | K35: HÌNH THỨC TT | L35: GHI CHÚ KIỂM TOÁN THUẾ
A36: 4.1 | B36: Công bốc xếp chuyển tải 'thùng đấu thùng' | C36: [Số lượng thùng bốc] | D36: Thùng | E36: 0 | F36: 0 | G36: 0 | H36: 0 | I36: =G36+H36 | J36: Bảng kê 01/TNDN & Mẫu 08 | K36: Tiền mặt | L36: Có CCCD Tổ trưởng (Chi phí hợp lý TT96)
A37: 4.2 | B37: Phí xử lý hồ sơ thay đổi phương án giao hàng | C37: Công văn 15/CV-GSS hủy xuất cảnh xe sang hàng | D37: Vụ | E37: 1 | F37: 0 | G37: 0 | H37: 0 | I37: =G37+H37 | J37: Công văn 15 có mộc Hải quan | K37: Chuyển khoản | L37: Phát sinh đột xuất tại hiện trường Lao Bảo
A38: 4.3 | B38: Tiền phòng khách sạn nhân viên hiện trường | C38: [Số đêm lưu trú] | D38: Đêm | E38: 0 | F38: 0 | G38: =E38*F38 | H38: =G38*0.08 | I38: =G38+H38 | J38: HĐ 00001188 (Dư Hùng Phát) | K38: Hoàn ứng | L38: Hóa đơn VAT 8% (Giấy thanh toán KT-LOG-07)
A39: 4.4 | B39: [Người dùng nhập thêm khoản phát sinh 01] | C39: Mô tả khoản chi phí phát sinh thực tế... | D39: Gói | E39: 0 | F39: 0 | G39: 0 | H39: =G39*0.08 | I39: =G39+H39 | J39: Chứng từ kèm theo... | K39: [Hình thức] | L39: Ghi chú thuế...
A40: 4.5 | B40: [Người dùng nhập thêm khoản phát sinh 02] | C40: Mô tả khoản chi phí phát sinh thực tế... | D40: Gói | E40: 0 | F40: 0 | G40: 0 | H40: =G40*0.08 | I40: =G40+H40 | J40: Chứng từ kèm theo... | K40: [Hình thức] | L40: Ghi chú thuế...
A41: 4.6 | B41: [Người dùng nhập thêm khoản phát sinh 03] | C41: Mô tả khoản chi phí phát sinh thực tế... | D41: Gói | E41: 0 | F41: 0 | G41: 0 | H41: =G41*0.08 | I41: =G41+H41 | J41: Chứng từ kèm theo... | K41: [Hình thức] | L41: Ghi chú thuế...
A42: 4.7 | B42: [Người dùng nhập thêm khoản phát sinh 04] | C42: Mô tả khoản chi phí phát sinh thực tế... | D42: Gói | E42: 0 | F42: 0 | G42: 0 | H42: =G42*0.08 | I42: =G42+H42 | J42: Chứng từ kèm theo... | K42: [Hình thức] | L42: Ghi chú thuế...
A43: 4.8 | B43: [Người dùng nhập thêm khoản phát sinh 05] | C43: Mô tả khoản chi phí phát sinh thực tế... | D43: Gói | E43: 0 | F43: 0 | G43: 0 | H43: =G43*0.08 | I43: =G43+H43 | J43: Chứng từ kèm theo... | K43: [Hình thức] | L43: Ghi chú thuế...
A44: — | B44: CỘNG TOÀN BỘ PHỤ PHÍ PHÁT SINH NGOÀI | C44: Tự động cộng dồn các khoản chi thực tế và nhập thêm | D44: Mục | E44: =COUNTIF(G36:G43,">0") | G44: =SUM(G36:G43) | H44: =SUM(H36:H43) | I44: =SUM(I36:I43) | J44: Bảng kê + Hóa đơn lẻ | K44: Đa dạng | L44: Tự động tính thuế và phân bổ vào P&L
A46: PHẦN V: BẢNG TỔNG HỢP P&L — PHÂN ĐỊNH 2 TẦNG LỢI NHUẬN (TRƯỚC KHI HOÀN THUẾ & SAU KHI HOÀN THUẾ)
A48: A | B48: TỔNG DOANH THU THỰC NHẬN TỪ 2 ĐỢT NGOẠI TỆ (FCA) | G48: =G19 | J48: Công thức Excel tự động
A49: B | B49: 1. Chi phí Giá vốn mua hàng Thiên Long (Phần II) | G49: =G24 | J49: Công thức Excel tự động
A50: C | B50: 2. Chi phí Vận tải & Logistics chính tuyến (Phần III) | G50: =G32 | J50: Công thức Excel tự động
A51: D | B51: 3. Phụ phí phát sinh ngoài thực tế cửa khẩu & hiện trường (Phần IV) | G51: =G44 | J51: Công thức Excel tự động
...

Sheet SO_HOAN_THUE_TK1331
A1: CÔNG TY TNHH GLOBAL SOLUTION SERVICE (G-SS CO.,LTD)
A2: SỔ THEO DÕI CHI TIẾT THUẾ GTGT ĐẦU VÀO ĐƯỢC KHẤU TRỪ & HOÀN THUẾ XUẤT KHẨU (TK 1331)
A3: Căn cứ Thông tư 200/2014/TT-BTC & Thông tư 80/2021/TT-BTC — Chỉ ghi nhận hóa đơn thực tế phát sinh
A5: STT | B5: NGÀY HÓA ĐƠN | C5: MÃ ĐƠN | D5: KÝ HIỆU HĐ | E5: SỐ HÓA ĐƠN | F5: TÊN NHÀ CUNG CẤP / ĐƠN VỊ BÁN | G5: MST BÊN BÁN | H5: NỘI DUNG MẶT HÀNG / DỊCH VỤ | I5: DOANH SỐ CHƯA THUẾ (VNĐ) | J5: THUẾ SUẤT | K5: THUẾ GTGT 8% (VNĐ) | L5: LŨY KẾ SỐ DƯ TK 1331 | M5: CHỨNG TỪ THANH TOÁN MB BANK | N5: ĐIỀU KIỆN HOÀN THUẾ
A6: 1 | B6: 21/09/2026 | C6: 269901 | D6: 1C26TTL | E6: 00000845 | F6: Công ty TNHH Đầu tư TM CN Thiên Long | G6: 2601077991 | H6: 1.300 thùng Snack Quẩy Giòn Giòn | I6: 358600000 | J6: 8% | K6: =I6*0.08 | L6: =K6 | M6: UNC MB 21092601 (387.288.000 đ) | N6: ĐÃ ĐẠT (Thanh toán NH)
A7: 2 | B7: 22/09/2026 | C7: 269901 | D7: 1C26TVT | E7: 00000217 | F7: Công ty CP Dịch vụ Vận tải Vĩnh Thành | G7: 0108992145 | H7: Cước vận chuyển container HOWO Lao Bảo | I7: 22000000 | J7: 8% | K7: =I7*0.08 | L7: =L6+K7 | M7: UNC MB 22092602 (23.760.000 đ) | N7: ĐÃ ĐẠT (Thanh toán NH)
A8: 3 | B8: 23/09/2026 | C8: 269901 | D8: 1C26TVT | E8: 00000218 | F8: Công ty CP Dịch vụ Vận tải Vĩnh Thành | G8: 0108992145 | H8: Phí lưu xe HOWO 2 ngày bãi Lao Bảo | I8: 4629630 | J8: 8% | K8: =I8*0.08 | L8: =L7+K8 | M8: UNC MB 23092601 (5.000.000 đ) | N8: ĐÃ ĐẠT (Thanh toán NH)
A9: 4 | B9: 23/09/2026 | C9: 269901 | D9: 1C26TDH | E9: 00001188 | F9: Khách sạn Dư Hùng Phát Lao Bảo | G9: 3200654321 | H9: Tiền phòng nhân viên hiện trường (2 đêm) | I9: 740740 | J9: 8% | K9: =I9*0.08 | L9: =L8+K9 | M9: Giấy thanh toán hoàn ứng kèm HĐ | N9: ĐÃ ĐẠT (Hóa đơn hợp pháp)
A10: 5 | B10: 24/09/2026 | C10: 269901 | D10: 1C26TBA | E10: 00000512 | F10: Đại lý Hải quan Bình An | G10: 0109123456 | H10: Phí dịch vụ hải quan & C/O Form D | I10: 9229630 | J10: 8% | K10: =I10*0.08 | L10: =L9+K10 | M10: UNC MB 24092601 (9.968.000 đ) | N10: ĐÃ ĐẠT (Thanh toán NH)
A11: 6 | C11: [Chờ phát sinh] | L11: =IF(K11="","",L10+K11)
A12: 7 | C12: [Chờ phát sinh] | L12: =IF(K12="","",L11+K12)
A13: 8 | C13: [Chờ phát sinh] | L13: =IF(K13="","",L12+K13)
A14: 9 | C14: [Chờ phát sinh] | L14: =IF(K14="","",L13+K14)
A15: 10 | C15: [Chờ phát sinh] | L15: =IF(K15="","",L14+K15)
A16: — | B16: TỔNG CỘNG | C16: LŨY KẾ HÓA ĐƠN THỰC TẾ ĐÃ PHÁT SINH | I16: =SUM(I6:I15) | J16: 8% | K16: =SUM(K6:K15) | L16: =K6+K7+K8+K9+K10 | M16: ĐỐI SOÁT KHỚP 100% SỔ PHỤ MB BANK | N16: =IF(L16>=300000000, "ĐỦ ĐIỀU KIỆN HOÀN THUẾ", "ĐANG TÍCH LŨY (Chưa đủ 300M)")

Sheet CHECKLIST_4_WAY_MATCHING
A1: CÔNG TY TNHH GLOBAL SOLUTION SERVICE (G-SS CO.,LTD)
A2: CHECKLIST ĐỐI SOÁT HỒ SƠ HOÀN THUẾ GTGT 0% (4-WAY MATCHING AUDIT)
A3: Đối chiếu 4 bên: (1) Hợp đồng ngoại thương — (2) Tờ khai hải quan thông quan — (3) Hóa đơn GTGT — (4) Chứng từ thanh toán ngân hàng
A5: STT | B5: TRỤ CỘT KIỂM SOÁT | C5: TIÊU CHÍ ĐỐI SOÁT CHI TIẾT | D5: CĂN CỨ PHÁP LÝ & QUY ĐỊNH | E5: ĐƠN 269901 (THỰC TẾ) | F5: ĐƠN HÀNG TIẾP THEO (MẪU) | G5: ĐÁNH GIÁ RỦI RO & KHUYẾN NGHỊ CFO
A6: 1 | B6: 1. HỢP ĐỒNG NGOẠI THƯƠNG | C6: Hợp đồng ký kết với thương nhân nước ngoài | D6: Điều 16 TT 219/2013 | E6: [ĐÃ ĐẠT] | F6: [CHỜ HỢP ĐỒNG MỚI] | G6: Bắt buộc có chữ ký & con dấu đối tác
A7: 2 | B7: 1. HỢP ĐỒNG NGOẠI THƯƠNG | C7: Điều khoản thanh toán qua Ngân hàng T/T | D7: Khoản 2 Điều 16 TT 219 | E7: [ĐÃ ĐẠT] | F7: [CHỜ HỢP ĐỒNG MỚI] | G7: Không chấp nhận thanh toán tiền mặt
A8: 3 | B8: 2. TỜ KHAI HẢI QUAN | C8: Tờ khai xuất khẩu B11 đã Thông quan | D8: Thông tư 38/2015 & 39/2018 | E8: [ĐÃ ĐẠT] | F8: [CHỜ THÔNG QUAN] | G8: Xác nhận thực xuất trên hệ thống VNACCS
A9: 4 | B9: 2. TỜ KHAI HẢI QUAN | C9: Giấy chứng nhận xuất xứ C/O Form D | D9: Hiệp định ATIGA | E9: [ĐÃ ĐẠT] | F9: [CHỜ CẤP ECOSYS] | G9: Cấp điện tử trên eCoSys của Bộ Công Thương
A10: 5 | B10: 3. HÓA ĐƠN GTGT | C10: Hóa đơn xuất khẩu GTGT 0% phát hành hợp lệ | D10: Nghị định 123/2020 | E10: [ĐÃ ĐẠT] | F10: [CHỜ XUẤT HĐ 0%] | G10: Xuất trong ngày hoàn thành thông quan B11
A11: 6 | B11: 3. HÓA ĐƠN GTGT | C11: Hóa đơn mua hàng đầu vào (Thiên Long 8%) | D11: Thông tư 78/2021 | E11: [ĐÃ ĐẠT] | F11: [CHỜ NHẬN HĐ ĐẦU VÀO] | G11: Tra cứu hợp pháp trên cổng hoadondientu.gdt.gov.vn
A12: 7 | B12: 3. HÓA ĐƠN GTGT | C12: Hóa đơn vận tải & chi phí logistics (8%) | D12: Thông tư 78/2021 | E12: [ĐÃ ĐẠT] | F12: [CHỜ HĐ VẬN TẢI] | G12: Đầy đủ biên bản giao nhận & lộ trình xe
A13: 8 | B13: 4. CHỨNG TỪ NGÂN HÀNG | C13: Điện chuyển tiền kiều hối USD (Swift MT103) | D13: Điều 16 TT 219/2013 | E13: [ĐÃ ĐẠT] | F13: [CHỜ BÁO CÓ USD] | G13: Tên người chuyển tiền khớp 100% người mua
A14: 9 | B14: 4. CHỨNG TỪ NGÂN HÀNG | C14: Giấy báo Có tài khoản ngoại tệ MB Bank | D14: Thông tư 200/2014 | E14: [ĐÃ ĐẠT] | F14: [CHỜ BÁO CÓ USD] | G14: Số tiền khớp từng đợt giải ngân hợp đồng
A15: 10 | B15: 4. CHỨNG TỪ NGÂN HÀNG | C15: Ủy nhiệm chi (UNC) thanh toán đầu vào | D15: Khoản 3 Điều 15 TT 219 | E15: [ĐÃ ĐẠT] | F15: [CHỜ UNC ĐẦU VÀO] | G15: Bắt buộc chuyển khoản cho hóa đơn ≥ 20 triệu VNĐ
A16: 11 | B16: 5. QUỸ HOÀN THUẾ | C16: Dồn tích lũy thuế GTGT đầu vào ≥ 300 triệu | D16: Điều 28 Luật Thuế GTGT | E16: 37,2M đ (Đang dồn tích lũy) | F16: Chờ dồn tích lũy tiếp | G16: Dồn tích lũy qua các đơn tiếp theo đến khi đủ ≥ 300M

Sheet DONG_BO_MANIFEST_269901
A1: DỮ LIỆU ĐỒNG BỘ NGUỒN SỰ THẬT DUY NHẤT (SSOT) — ORDER MANIFEST 269901
A2: Tự động trích xuất từ file: order_manifest_269901.json (Khóa dữ liệu kiểm toán)
A4: STT | B4: TRƯỜNG DỮ LIỆU (FIELD NAME) | C4: GIÁ TRỊ SSOT XÁC THỰC | D4: ĐƠN VỊ TÍNH / QUY CÁCH | E4: GHI CHÚ HỆ THỐNG / PHÂN QUYỀN
A5: 1 | B5: order_id | C5: 269901 | D5: Mã đơn hàng nội bộ (YYMMDDNN: 26-9-9-01) | E5: Khóa SSOT
A6: 2 | B6: contract_code | C6: GSSDIX_FCA_269901 | D6: Số Hợp đồng Ngoại thương chuẩn | E6: Pháp lý
A7: 3 | B7: buyer_name | C7: DUANGMANEE IMPORT-EXPORT CO., LTD | D7: Khách hàng mua (Thái Lan) | E7: Khách hàng
A8: 4 | B8: seller_name | C8: CÔNG TY TNHH GLOBAL SOLUTION SERVICE | D8: Bên bán xuất khẩu (G-SS) | E8: Chủ thể
A9: 5 | B9: seller_tax_id | C9: 0109469047 | D9: Mã số thuế GSS | E9: Pháp nhân
A10: 6 | B10: customs_declaration_no | C10: 107382910430 | D10: Số Tờ khai Hải quan B11 | E10: Hải quan
A11: 7 | B11: customs_channel | C11: Vàng (Kiểm tra hồ sơ) | D11: Phân luồng Hải quan | E11: Thông quan
A12: 8 | B12: export_date | C12: 21/09/2026 | D12: Ngày xuất cảnh thực tế | E12: Thời gian
A13: 9 | B13: product_name | C13: Snack Quẩy Giòn Giòn | D13: Tên thương mại thành phẩm | E13: Sản phẩm
A14: 10 | B14: hs_code | C14: 1905.90.90 | D14: Mã HS Code xuất khẩu | E14: Thuế 0%
A15: 11 | B15: package_qty | C15: 1.300 | D15: Thùng carton 5 lớp | E15: Số lượng
A16: 12 | B16: cups_qty | C16: 390.000 | D16: Cốc thành phẩm (22g/cốc) | E16: Số lượng
... A26: 22 | B26: net_profit_tier2_post_refund | C26: 81.848.790 đ | D26: Lãi ròng Tầng 2 (Sau khi hoàn thuế) | E26: EAT 2 (15,32%)

Sheet HUONG_DAN_SU_DUNG
A1: HƯỚNG DẪN QUẢN TRỊ TÀI CHÍNH & VẬN HÀNH FILE EXCEL ALL-IN-ONE (MASTER WORKBOOK)
A2: Dành cho Bộ phận Kế toán & Ban Giám đốc — Công ty TNHH Global Solution Service (G-SS CO.,LTD)
A4: ★ BỘ QUY TẮC ĐẶT TÊN MÃ ĐƠN HÀNG (ORDER ID) & MÃ HỢP ĐỒNG / PO XNK (QUY CHUẨN BAN GIÁM ĐỐC)
A5: • CẤU TRÚC MÃ ĐƠN HÀNG (SHORT ID): YYMMDDNN
A6: - YY: 2 chữ số cuối của năm tạo nháp / lên phương án (ví dụ '26' là năm 2026).
A7: - MM: Tháng tạo nháp đơn hàng (ví dụ: '9' hoặc '10').
A8: - DD: Ngày tạo nháp đơn hàng trong tháng (ví dụ: '9', '15', '27').
A9: - NN: Số thứ tự đơn hàng được thành lập trong ngày hôm đó ('01', '02', '03'...).
A10: • CẤU TRÚC MÃ HỢP ĐỒNG / PO ĐẦY ĐỦ: GSS[BUYER]_[INCOTERMS]_[YYMMDDNN]
A11: - GSS: Mã pháp nhân Bên bán (Global Solution Service).
A12: - DIX: Mã viết tắt Khách hàng mua (Duangmanee Import-Export Co., Ltd).
A13: - FCA: Điều kiện thương mại quốc tế Incoterms 2020 (giao tại cửa khẩu).
... A65: - Tiền thuế được treo tích lũy tại TK 1331 qua từng đơn hàng. Khi quỹ tích lũy đạt ≥ 300M, Kế toán nộp hồ sơ thu tiền về!
